<?xml version="1.0" encoding="utf-8"?>
<robot name="sim_pusher" xmlns:xacro="http://wiki.ros.org/xacro">
  <material name="red">
    <color rgba="0.8 0.0 0.0 1.0"/>
  </material>
  <material name="black">
    <color rgba="0.0 0.0 0.0 1.0"/>
  </material>

  <link name="base_link">
	 <inertial>
     <mass value="1.0"/>
     <inertia ixx="1.0" ixy="0" ixz="0" iyy="1.0" iyz="0" izz="1.0"/>
     <origin rpy="0 0 0" xyz="0 0 0"/>
    </inertial>
  </link>
  <!--   &#60;&#33;&#45;&#45; TODO &#45;&#45;&#62; -->
  <!--   <inertial> -->
  <!--     <origin rpy="0 0 0" xyz="0 0 0.03"/> -->
  <!--     <mass value="100"/> -->
  <!--     <inertia ixx="100"  ixy="0"  ixz="0" iyy="100" iyz="0" izz="100" /> -->
  <!--   </inertial> -->
  <!--  -->
  <!--   <visual> -->
  <!--     <origin rpy="0 0 0" xyz="0 0 0"/> -->
  <!--     <geometry> -->
  <!--       &#60;&#33;&#45;&#45; <cylinder radius="0.4" length="0.06"/> &#45;&#45;&#62; -->
  <!--       <box size="0.8 0.8 0.06"/> -->
  <!--     </geometry> -->
  <!--     <material name="black"/> -->
  <!--   </visual> -->
  <!--  -->
  <!--   <collision> -->
  <!--     <origin rpy="0 0 0" xyz="0 0 0"/> -->
  <!--     <geometry> -->
  <!--       &#60;&#33;&#45;&#45; <cylinder radius="0.4" length="0.06"/> &#45;&#45;&#62; -->
  <!--       <box size="0.8 0.8 0.06"/> -->
  <!--     </geometry> -->
  <!--   </collision> -->
  <!-- </link> -->

	<joint name="pusher_joint_x" type="prismatic">
    <parent link="base_link"/>
    <child link="dummy_link"/>
    <axis xyz="1 0 0"/>
    <origin rpy="0 0 0" xyz="0 0 0.06"/>
    <limit effort="0" velocity="1000.0"/>
    <!-- <dynamics damping="1.0" friction="1.0"/> -->
  </joint>

	<link name="dummy_link">
	 <inertial>
     <mass value="1.0"/>
     <inertia ixx="1.0" ixy="0" ixz="0" iyy="1.0" iyz="0" izz="1.0"/>
     <origin rpy="0 0 0" xyz="0 0 0"/>
    </inertial>
  </link>

	<joint name="pusher_joint_y" type="prismatic">
    <parent link="dummy_link"/>
    <child link="pusher_link"/>
    <axis xyz="0 1 0"/>
    <origin rpy="0 0 0" xyz="0 0 0"/>
    <limit effort="0" velocity="1000.0"/>
    <!-- <dynamics damping="1.0" friction="1.0"/> -->
  </joint>

  <!-- <joint name="pusher_joint" type="fixed"> -->
  <!--   <origin rpy="0 0 0" xyz="0 0 0.03"/> -->
  <!--   <axis xyz="0 0 1"/> -->
  <!--   <parent link="base_link"/> -->
  <!--   <child link="pusher_link"/> -->
  <!-- </joint> -->

  <link name="pusher_link">
    <!-- TODO -->
    <inertial>
      <origin rpy="0 0 0" xyz="0 0 0"/>
      <mass value="1"/>
      <inertia ixx="1"  ixy="0"  ixz="0" iyy="1" iyz="0" izz="1" />
    </inertial>

    <visual>
      <origin rpy="0 0 0" xyz="0 0 0"/>
      <geometry>
        <sphere radius="0.05"/>
      </geometry>
      <material name="red"/>
    </visual>

    <collision>
      <origin rpy="0 0 0" xyz="0 0 0"/>
      <geometry>
        <sphere radius="0.05"/>
      </geometry>
    </collision>
  </link>

</robot>
